<?xml version="1.0" encoding="UTF-8"?>
<testng-results skipped="23" failed="1" ignored="0" total="25" passed="1">
  <reporter-output>
  </reporter-output>
  <suite name="Default suite" duration-ms="266308" started-at="2017-08-03T16:02:54Z" finished-at="2017-08-03T16:07:20Z">
    <groups>
      <group name="Regression_Chrome">
        <method signature="Test_ErrorFix.Order_Certificates(java.lang.String, java.lang.String)[pri:1, instance:Sanity_Test.Test_ErrorFix@63753b6d]" name="Order_Certificates" class="Sanity_Test.Test_ErrorFix"/>
      </group> <!-- Regression_Chrome -->
      <group name="Regression">
        <method signature="Test_ErrorFix.Order_Certificates(java.lang.String, java.lang.String)[pri:1, instance:Sanity_Test.Test_ErrorFix@63753b6d]" name="Order_Certificates" class="Sanity_Test.Test_ErrorFix"/>
      </group> <!-- Regression -->
      <group name="BS_Regression">
        <method signature="Test_ErrorFix.Order_Certificates(java.lang.String, java.lang.String)[pri:1, instance:Sanity_Test.Test_ErrorFix@63753b6d]" name="Order_Certificates" class="Sanity_Test.Test_ErrorFix"/>
      </group> <!-- BS_Regression -->
    </groups>
    <test name="Default test" duration-ms="266308" started-at="2017-08-03T16:02:54Z" finished-at="2017-08-03T16:07:20Z">
      <class name="Sanity_Test.Test_ErrorFix">
        <test-method status="PASS" signature="beforeTest()[pri:0, instance:Sanity_Test.Test_ErrorFix@63753b6d]" name="beforeTest" is-config="true" duration-ms="3889" started-at="2017-08-03T17:02:54Z" finished-at="2017-08-03T17:02:58Z">
          <reporter-output>
          </reporter-output>
        </test-method> <!-- beforeTest -->
        <test-method status="PASS" signature="User_Login()[pri:0, instance:Sanity_Test.Test_ErrorFix@63753b6d]" name="User_Login" is-config="true" duration-ms="24577" started-at="2017-08-03T17:02:58Z" finished-at="2017-08-03T17:03:23Z">
          <reporter-output>
          </reporter-output>
        </test-method> <!-- User_Login -->
        <test-method status="PASS" signature="Order_Certificates(java.lang.String, java.lang.String)[pri:1, instance:Sanity_Test.Test_ErrorFix@63753b6d]" name="Order_Certificates" duration-ms="128060" started-at="2017-08-03T17:03:23Z" data-provider="OrderProduct_Data" finished-at="2017-08-03T17:05:31Z">
          <params>
            <param index="0">
              <value>
                <![CDATA[Order Products Test --> Order_Symantec Secure Site]]>
              </value>
            </param>
            <param index="1">
              <value>
                <![CDATA[Symantec Secure Site]]>
              </value>
            </param>
          </params>
          <reporter-output>
          </reporter-output>
        </test-method> <!-- Order_Certificates -->
        <test-method status="PASS" signature="User_Logout(org.testng.ITestResult)[pri:0, instance:Sanity_Test.Test_ErrorFix@63753b6d]" name="User_Logout" is-config="true" duration-ms="5787" started-at="2017-08-03T17:05:31Z" finished-at="2017-08-03T17:05:36Z">
          <params>
            <param index="0">
              <value>
                <![CDATA[[TestResult name=Order_Certificates status=SUCCESS method=Test_ErrorFix.Order_Certificates(java.lang.String, java.lang.String)[pri:1, instance:Sanity_Test.Test_ErrorFix@63753b6d] output={null}]]]>
              </value>
            </param>
          </params>
          <reporter-output>
          </reporter-output>
        </test-method> <!-- User_Logout -->
        <test-method status="PASS" signature="User_Login()[pri:0, instance:Sanity_Test.Test_ErrorFix@63753b6d]" name="User_Login" is-config="true" duration-ms="21785" started-at="2017-08-03T17:05:36Z" finished-at="2017-08-03T17:05:58Z">
          <reporter-output>
          </reporter-output>
        </test-method> <!-- User_Login -->
        <test-method status="FAIL" signature="Order_Certificates(java.lang.String, java.lang.String)[pri:1, instance:Sanity_Test.Test_ErrorFix@63753b6d]" name="Order_Certificates" duration-ms="78649" started-at="2017-08-03T17:05:58Z" data-provider="OrderProduct_Data" finished-at="2017-08-03T17:07:17Z">
          <params>
            <param index="0">
              <value>
                <![CDATA[Order Products Test --> Order_Symantec Secure Site EV]]>
              </value>
            </param>
            <param index="1">
              <value>
                <![CDATA[Symantec Secure Site EV]]>
              </value>
            </param>
          </params>
          <exception class="java.lang.AssertionError">
            <message>
              <![CDATA[Exception org.openqa.selenium.NoSuchElementException: no such element: Unable to locate element: {"method":"xpath","selector":".//*[@class='btn btn-success btn-small']"}
  (Session info: chrome=60.0.3112.78)
  (Driver info: chromedriver=2.29.461591 (62ebf098771772160f391d75e589dc567915b233),platform=Windows NT 10.0.15063 x86_64) (WARNING: The server did not provide any stacktrace information)
Command duration or timeout: 30.06 seconds
For documentation on this error, please visit: http://seleniumhq.org/exceptions/no_such_element.html
Build info: version: 'unknown', revision: 'unknown', time: 'unknown'
System info: host: 'SSL247DEV004', ip: '192.168.232.1', os.name: 'Windows 10', os.arch: 'amd64', os.version: '10.0', java.version: '1.8.0_121'
Driver info: org.openqa.selenium.chrome.ChromeDriver
Capabilities [{applicationCacheEnabled=false, rotatable=false, mobileEmulationEnabled=false, networkConnectionEnabled=false, chrome={chromedriverVersion=2.29.461591 (62ebf098771772160f391d75e589dc567915b233), userDataDir=C:\Users\GIDEON~1\AppData\Local\Temp\scoped_dir9204_20164}, takesHeapSnapshot=true, pageLoadStrategy=normal, databaseEnabled=false, handlesAlerts=true, hasTouchScreen=false, version=60.0.3112.78, platform=XP, browserConnectionEnabled=false, nativeEvents=true, acceptSslCerts=true, locationContextEnabled=true, webStorageEnabled=true, browserName=chrome, takesScreenshot=true, javascriptEnabled=true, cssSelectorsEnabled=true, unexpectedAlertBehaviour=}]
Session ID: c02773fe653d945de6ac030e6084a243
*** Element info: {Using=xpath, value=.//*[@class='btn btn-success btn-small']}]]>
            </message>
            <full-stacktrace>
              <![CDATA[java.lang.AssertionError: Exception org.openqa.selenium.NoSuchElementException: no such element: Unable to locate element: {"method":"xpath","selector":".//*[@class='btn btn-success btn-small']"}
  (Session info: chrome=60.0.3112.78)
  (Driver info: chromedriver=2.29.461591 (62ebf098771772160f391d75e589dc567915b233),platform=Windows NT 10.0.15063 x86_64) (WARNING: The server did not provide any stacktrace information)
Command duration or timeout: 30.06 seconds
For documentation on this error, please visit: http://seleniumhq.org/exceptions/no_such_element.html
Build info: version: 'unknown', revision: 'unknown', time: 'unknown'
System info: host: 'SSL247DEV004', ip: '192.168.232.1', os.name: 'Windows 10', os.arch: 'amd64', os.version: '10.0', java.version: '1.8.0_121'
Driver info: org.openqa.selenium.chrome.ChromeDriver
Capabilities [{applicationCacheEnabled=false, rotatable=false, mobileEmulationEnabled=false, networkConnectionEnabled=false, chrome={chromedriverVersion=2.29.461591 (62ebf098771772160f391d75e589dc567915b233), userDataDir=C:\Users\GIDEON~1\AppData\Local\Temp\scoped_dir9204_20164}, takesHeapSnapshot=true, pageLoadStrategy=normal, databaseEnabled=false, handlesAlerts=true, hasTouchScreen=false, version=60.0.3112.78, platform=XP, browserConnectionEnabled=false, nativeEvents=true, acceptSslCerts=true, locationContextEnabled=true, webStorageEnabled=true, browserName=chrome, takesScreenshot=true, javascriptEnabled=true, cssSelectorsEnabled=true, unexpectedAlertBehaviour=}]
Session ID: c02773fe653d945de6ac030e6084a243
*** Element info: {Using=xpath, value=.//*[@class='btn btn-success btn-small']}
	at org.testng.Assert.fail(Assert.java:93)
	at Sanity_Test.Test_ErrorFix.Order_Certificates(Test_ErrorFix.java:520)
	at sun.reflect.NativeMethodAccessorImpl.invoke0(Native Method)
	at sun.reflect.NativeMethodAccessorImpl.invoke(NativeMethodAccessorImpl.java:62)
	at sun.reflect.DelegatingMethodAccessorImpl.invoke(DelegatingMethodAccessorImpl.java:43)
	at java.lang.reflect.Method.invoke(Method.java:498)
	at org.testng.internal.MethodInvocationHelper.invokeMethod(MethodInvocationHelper.java:108)
	at org.testng.internal.Invoker.invokeMethod(Invoker.java:661)
	at org.testng.internal.Invoker.invokeTestMethod(Invoker.java:869)
	at org.testng.internal.Invoker.invokeTestMethods(Invoker.java:1193)
	at org.testng.internal.TestMethodWorker.invokeTestMethods(TestMethodWorker.java:126)
	at org.testng.internal.TestMethodWorker.run(TestMethodWorker.java:109)
	at org.testng.TestRunner.privateRun(TestRunner.java:744)
	at org.testng.TestRunner.run(TestRunner.java:602)
	at org.testng.SuiteRunner.runTest(SuiteRunner.java:380)
	at org.testng.SuiteRunner.runSequentially(SuiteRunner.java:375)
	at org.testng.SuiteRunner.privateRun(SuiteRunner.java:340)
	at org.testng.SuiteRunner.run(SuiteRunner.java:289)
	at org.testng.SuiteRunnerWorker.runSuite(SuiteRunnerWorker.java:52)
	at org.testng.SuiteRunnerWorker.run(SuiteRunnerWorker.java:86)
	at org.testng.TestNG.runSuitesSequentially(TestNG.java:1301)
	at org.testng.TestNG.runSuitesLocally(TestNG.java:1226)
	at org.testng.TestNG.runSuites(TestNG.java:1144)
	at org.testng.TestNG.run(TestNG.java:1115)
	at org.testng.remote.AbstractRemoteTestNG.run(AbstractRemoteTestNG.java:132)
	at org.testng.remote.RemoteTestNG.initAndRun(RemoteTestNG.java:230)
	at org.testng.remote.RemoteTestNG.main(RemoteTestNG.java:76)
]]>
            </full-stacktrace>
          </exception> <!-- java.lang.AssertionError -->
          <reporter-output>
          </reporter-output>
        </test-method> <!-- Order_Certificates -->
        <test-method status="FAIL" signature="User_Logout(org.testng.ITestResult)[pri:0, instance:Sanity_Test.Test_ErrorFix@63753b6d]" name="User_Logout" is-config="true" duration-ms="3376" started-at="2017-08-03T17:07:17Z" finished-at="2017-08-03T17:07:20Z">
          <params>
            <param index="0">
              <value>
                <![CDATA[[TestResult name=Order_Certificates status=FAILURE method=Test_ErrorFix.Order_Certificates(java.lang.String, java.lang.String)[pri:1, instance:Sanity_Test.Test_ErrorFix@63753b6d] output={null}]]]>
              </value>
            </param>
          </params>
          <exception class="java.lang.AssertionError">
            <message>
              <![CDATA[Log Out not visible]]>
            </message>
            <full-stacktrace>
              <![CDATA[java.lang.AssertionError: Log Out not visible
	at org.testng.Assert.fail(Assert.java:93)
	at Sanity_Test.Test_ErrorFix.User_Logout(Test_ErrorFix.java:119)
	at sun.reflect.NativeMethodAccessorImpl.invoke0(Native Method)
	at sun.reflect.NativeMethodAccessorImpl.invoke(NativeMethodAccessorImpl.java:62)
	at sun.reflect.DelegatingMethodAccessorImpl.invoke(DelegatingMethodAccessorImpl.java:43)
	at java.lang.reflect.Method.invoke(Method.java:498)
	at org.testng.internal.MethodInvocationHelper.invokeMethod(MethodInvocationHelper.java:108)
	at org.testng.internal.Invoker.invokeConfigurationMethod(Invoker.java:523)
	at org.testng.internal.Invoker.invokeConfigurations(Invoker.java:224)
	at org.testng.internal.Invoker.invokeMethod(Invoker.java:723)
	at org.testng.internal.Invoker.invokeTestMethod(Invoker.java:869)
	at org.testng.internal.Invoker.invokeTestMethods(Invoker.java:1193)
	at org.testng.internal.TestMethodWorker.invokeTestMethods(TestMethodWorker.java:126)
	at org.testng.internal.TestMethodWorker.run(TestMethodWorker.java:109)
	at org.testng.TestRunner.privateRun(TestRunner.java:744)
	at org.testng.TestRunner.run(TestRunner.java:602)
	at org.testng.SuiteRunner.runTest(SuiteRunner.java:380)
	at org.testng.SuiteRunner.runSequentially(SuiteRunner.java:375)
	at org.testng.SuiteRunner.privateRun(SuiteRunner.java:340)
	at org.testng.SuiteRunner.run(SuiteRunner.java:289)
	at org.testng.SuiteRunnerWorker.runSuite(SuiteRunnerWorker.java:52)
	at org.testng.SuiteRunnerWorker.run(SuiteRunnerWorker.java:86)
	at org.testng.TestNG.runSuitesSequentially(TestNG.java:1301)
	at org.testng.TestNG.runSuitesLocally(TestNG.java:1226)
	at org.testng.TestNG.runSuites(TestNG.java:1144)
	at org.testng.TestNG.run(TestNG.java:1115)
	at org.testng.remote.AbstractRemoteTestNG.run(AbstractRemoteTestNG.java:132)
	at org.testng.remote.RemoteTestNG.initAndRun(RemoteTestNG.java:230)
	at org.testng.remote.RemoteTestNG.main(RemoteTestNG.java:76)
]]>
            </full-stacktrace>
          </exception> <!-- java.lang.AssertionError -->
          <reporter-output>
          </reporter-output>
        </test-method> <!-- User_Logout -->
        <test-method status="SKIP" signature="User_Login()[pri:0, instance:Sanity_Test.Test_ErrorFix@63753b6d]" name="User_Login" is-config="true" duration-ms="0" started-at="2017-08-03T17:07:20Z" finished-at="2017-08-03T17:07:20Z">
          <reporter-output>
          </reporter-output>
        </test-method> <!-- User_Login -->
        <test-method status="SKIP" signature="Order_Certificates(java.lang.String, java.lang.String)[pri:1, instance:Sanity_Test.Test_ErrorFix@63753b6d]" name="Order_Certificates" duration-ms="0" started-at="2017-08-03T17:07:20Z" data-provider="OrderProduct_Data" finished-at="2017-08-03T17:07:20Z">
          <exception class="java.lang.AssertionError">
            <message>
              <![CDATA[Log Out not visible]]>
            </message>
            <full-stacktrace>
              <![CDATA[java.lang.AssertionError: Log Out not visible
	at org.testng.Assert.fail(Assert.java:93)
	at Sanity_Test.Test_ErrorFix.User_Logout(Test_ErrorFix.java:119)
	at sun.reflect.NativeMethodAccessorImpl.invoke0(Native Method)
	at sun.reflect.NativeMethodAccessorImpl.invoke(NativeMethodAccessorImpl.java:62)
	at sun.reflect.DelegatingMethodAccessorImpl.invoke(DelegatingMethodAccessorImpl.java:43)
	at java.lang.reflect.Method.invoke(Method.java:498)
	at org.testng.internal.MethodInvocationHelper.invokeMethod(MethodInvocationHelper.java:108)
	at org.testng.internal.Invoker.invokeConfigurationMethod(Invoker.java:523)
	at org.testng.internal.Invoker.invokeConfigurations(Invoker.java:224)
	at org.testng.internal.Invoker.invokeMethod(Invoker.java:723)
	at org.testng.internal.Invoker.invokeTestMethod(Invoker.java:869)
	at org.testng.internal.Invoker.invokeTestMethods(Invoker.java:1193)
	at org.testng.internal.TestMethodWorker.invokeTestMethods(TestMethodWorker.java:126)
	at org.testng.internal.TestMethodWorker.run(TestMethodWorker.java:109)
	at org.testng.TestRunner.privateRun(TestRunner.java:744)
	at org.testng.TestRunner.run(TestRunner.java:602)
	at org.testng.SuiteRunner.runTest(SuiteRunner.java:380)
	at org.testng.SuiteRunner.runSequentially(SuiteRunner.java:375)
	at org.testng.SuiteRunner.privateRun(SuiteRunner.java:340)
	at org.testng.SuiteRunner.run(SuiteRunner.java:289)
	at org.testng.SuiteRunnerWorker.runSuite(SuiteRunnerWorker.java:52)
	at org.testng.SuiteRunnerWorker.run(SuiteRunnerWorker.java:86)
	at org.testng.TestNG.runSuitesSequentially(TestNG.java:1301)
	at org.testng.TestNG.runSuitesLocally(TestNG.java:1226)
	at org.testng.TestNG.runSuites(TestNG.java:1144)
	at org.testng.TestNG.run(TestNG.java:1115)
	at org.testng.remote.AbstractRemoteTestNG.run(AbstractRemoteTestNG.java:132)
	at org.testng.remote.RemoteTestNG.initAndRun(RemoteTestNG.java:230)
	at org.testng.remote.RemoteTestNG.main(RemoteTestNG.java:76)
]]>
            </full-stacktrace>
          </exception> <!-- java.lang.AssertionError -->
          <reporter-output>
          </reporter-output>
        </test-method> <!-- Order_Certificates -->
        <test-method status="SKIP" signature="User_Login()[pri:0, instance:Sanity_Test.Test_ErrorFix@63753b6d]" name="User_Login" is-config="true" duration-ms="0" started-at="2017-08-03T17:07:20Z" finished-at="2017-08-03T17:07:20Z">
          <reporter-output>
          </reporter-output>
        </test-method> <!-- User_Login -->
        <test-method status="SKIP" signature="Order_Certificates(java.lang.String, java.lang.String)[pri:1, instance:Sanity_Test.Test_ErrorFix@63753b6d]" name="Order_Certificates" duration-ms="0" started-at="2017-08-03T17:07:20Z" data-provider="OrderProduct_Data" finished-at="2017-08-03T17:07:20Z">
          <exception class="java.lang.AssertionError">
            <message>
              <![CDATA[Log Out not visible]]>
            </message>
            <full-stacktrace>
              <![CDATA[java.lang.AssertionError: Log Out not visible
	at org.testng.Assert.fail(Assert.java:93)
	at Sanity_Test.Test_ErrorFix.User_Logout(Test_ErrorFix.java:119)
	at sun.reflect.NativeMethodAccessorImpl.invoke0(Native Method)
	at sun.reflect.NativeMethodAccessorImpl.invoke(NativeMethodAccessorImpl.java:62)
	at sun.reflect.DelegatingMethodAccessorImpl.invoke(DelegatingMethodAccessorImpl.java:43)
	at java.lang.reflect.Method.invoke(Method.java:498)
	at org.testng.internal.MethodInvocationHelper.invokeMethod(MethodInvocationHelper.java:108)
	at org.testng.internal.Invoker.invokeConfigurationMethod(Invoker.java:523)
	at org.testng.internal.Invoker.invokeConfigurations(Invoker.java:224)
	at org.testng.internal.Invoker.invokeMethod(Invoker.java:723)
	at org.testng.internal.Invoker.invokeTestMethod(Invoker.java:869)
	at org.testng.internal.Invoker.invokeTestMethods(Invoker.java:1193)
	at org.testng.internal.TestMethodWorker.invokeTestMethods(TestMethodWorker.java:126)
	at org.testng.internal.TestMethodWorker.run(TestMethodWorker.java:109)
	at org.testng.TestRunner.privateRun(TestRunner.java:744)
	at org.testng.TestRunner.run(TestRunner.java:602)
	at org.testng.SuiteRunner.runTest(SuiteRunner.java:380)
	at org.testng.SuiteRunner.runSequentially(SuiteRunner.java:375)
	at org.testng.SuiteRunner.privateRun(SuiteRunner.java:340)
	at org.testng.SuiteRunner.run(SuiteRunner.java:289)
	at org.testng.SuiteRunnerWorker.runSuite(SuiteRunnerWorker.java:52)
	at org.testng.SuiteRunnerWorker.run(SuiteRunnerWorker.java:86)
	at org.testng.TestNG.runSuitesSequentially(TestNG.java:1301)
	at org.testng.TestNG.runSuitesLocally(TestNG.java:1226)
	at org.testng.TestNG.runSuites(TestNG.java:1144)
	at org.testng.TestNG.run(TestNG.java:1115)
	at org.testng.remote.AbstractRemoteTestNG.run(AbstractRemoteTestNG.java:132)
	at org.testng.remote.RemoteTestNG.initAndRun(RemoteTestNG.java:230)
	at org.testng.remote.RemoteTestNG.main(RemoteTestNG.java:76)
]]>
            </full-stacktrace>
          </exception> <!-- java.lang.AssertionError -->
          <reporter-output>
          </reporter-output>
        </test-method> <!-- Order_Certificates -->
        <test-method status="SKIP" signature="User_Login()[pri:0, instance:Sanity_Test.Test_ErrorFix@63753b6d]" name="User_Login" is-config="true" duration-ms="0" started-at="2017-08-03T17:07:20Z" finished-at="2017-08-03T17:07:20Z">
          <reporter-output>
          </reporter-output>
        </test-method> <!-- User_Login -->
        <test-method status="SKIP" signature="Order_Certificates(java.lang.String, java.lang.String)[pri:1, instance:Sanity_Test.Test_ErrorFix@63753b6d]" name="Order_Certificates" duration-ms="0" started-at="2017-08-03T17:07:20Z" data-provider="OrderProduct_Data" finished-at="2017-08-03T17:07:20Z">
          <exception class="java.lang.AssertionError">
            <message>
              <![CDATA[Log Out not visible]]>
            </message>
            <full-stacktrace>
              <![CDATA[java.lang.AssertionError: Log Out not visible
	at org.testng.Assert.fail(Assert.java:93)
	at Sanity_Test.Test_ErrorFix.User_Logout(Test_ErrorFix.java:119)
	at sun.reflect.NativeMethodAccessorImpl.invoke0(Native Method)
	at sun.reflect.NativeMethodAccessorImpl.invoke(NativeMethodAccessorImpl.java:62)
	at sun.reflect.DelegatingMethodAccessorImpl.invoke(DelegatingMethodAccessorImpl.java:43)
	at java.lang.reflect.Method.invoke(Method.java:498)
	at org.testng.internal.MethodInvocationHelper.invokeMethod(MethodInvocationHelper.java:108)
	at org.testng.internal.Invoker.invokeConfigurationMethod(Invoker.java:523)
	at org.testng.internal.Invoker.invokeConfigurations(Invoker.java:224)
	at org.testng.internal.Invoker.invokeMethod(Invoker.java:723)
	at org.testng.internal.Invoker.invokeTestMethod(Invoker.java:869)
	at org.testng.internal.Invoker.invokeTestMethods(Invoker.java:1193)
	at org.testng.internal.TestMethodWorker.invokeTestMethods(TestMethodWorker.java:126)
	at org.testng.internal.TestMethodWorker.run(TestMethodWorker.java:109)
	at org.testng.TestRunner.privateRun(TestRunner.java:744)
	at org.testng.TestRunner.run(TestRunner.java:602)
	at org.testng.SuiteRunner.runTest(SuiteRunner.java:380)
	at org.testng.SuiteRunner.runSequentially(SuiteRunner.java:375)
	at org.testng.SuiteRunner.privateRun(SuiteRunner.java:340)
	at org.testng.SuiteRunner.run(SuiteRunner.java:289)
	at org.testng.SuiteRunnerWorker.runSuite(SuiteRunnerWorker.java:52)
	at org.testng.SuiteRunnerWorker.run(SuiteRunnerWorker.java:86)
	at org.testng.TestNG.runSuitesSequentially(TestNG.java:1301)
	at org.testng.TestNG.runSuitesLocally(TestNG.java:1226)
	at org.testng.TestNG.runSuites(TestNG.java:1144)
	at org.testng.TestNG.run(TestNG.java:1115)
	at org.testng.remote.AbstractRemoteTestNG.run(AbstractRemoteTestNG.java:132)
	at org.testng.remote.RemoteTestNG.initAndRun(RemoteTestNG.java:230)
	at org.testng.remote.RemoteTestNG.main(RemoteTestNG.java:76)
]]>
            </full-stacktrace>
          </exception> <!-- java.lang.AssertionError -->
          <reporter-output>
          </reporter-output>
        </test-method> <!-- Order_Certificates -->
        <test-method status="SKIP" signature="User_Login()[pri:0, instance:Sanity_Test.Test_ErrorFix@63753b6d]" name="User_Login" is-config="true" duration-ms="0" started-at="2017-08-03T17:07:20Z" finished-at="2017-08-03T17:07:20Z">
          <reporter-output>
          </reporter-output>
        </test-method> <!-- User_Login -->
        <test-method status="SKIP" signature="Order_Certificates(java.lang.String, java.lang.String)[pri:1, instance:Sanity_Test.Test_ErrorFix@63753b6d]" name="Order_Certificates" duration-ms="0" started-at="2017-08-03T17:07:20Z" data-provider="OrderProduct_Data" finished-at="2017-08-03T17:07:20Z">
          <exception class="java.lang.AssertionError">
            <message>
              <![CDATA[Log Out not visible]]>
            </message>
            <full-stacktrace>
              <![CDATA[java.lang.AssertionError: Log Out not visible
	at org.testng.Assert.fail(Assert.java:93)
	at Sanity_Test.Test_ErrorFix.User_Logout(Test_ErrorFix.java:119)
	at sun.reflect.NativeMethodAccessorImpl.invoke0(Native Method)
	at sun.reflect.NativeMethodAccessorImpl.invoke(NativeMethodAccessorImpl.java:62)
	at sun.reflect.DelegatingMethodAccessorImpl.invoke(DelegatingMethodAccessorImpl.java:43)
	at java.lang.reflect.Method.invoke(Method.java:498)
	at org.testng.internal.MethodInvocationHelper.invokeMethod(MethodInvocationHelper.java:108)
	at org.testng.internal.Invoker.invokeConfigurationMethod(Invoker.java:523)
	at org.testng.internal.Invoker.invokeConfigurations(Invoker.java:224)
	at org.testng.internal.Invoker.invokeMethod(Invoker.java:723)
	at org.testng.internal.Invoker.invokeTestMethod(Invoker.java:869)
	at org.testng.internal.Invoker.invokeTestMethods(Invoker.java:1193)
	at org.testng.internal.TestMethodWorker.invokeTestMethods(TestMethodWorker.java:126)
	at org.testng.internal.TestMethodWorker.run(TestMethodWorker.java:109)
	at org.testng.TestRunner.privateRun(TestRunner.java:744)
	at org.testng.TestRunner.run(TestRunner.java:602)
	at org.testng.SuiteRunner.runTest(SuiteRunner.java:380)
	at org.testng.SuiteRunner.runSequentially(SuiteRunner.java:375)
	at org.testng.SuiteRunner.privateRun(SuiteRunner.java:340)
	at org.testng.SuiteRunner.run(SuiteRunner.java:289)
	at org.testng.SuiteRunnerWorker.runSuite(SuiteRunnerWorker.java:52)
	at org.testng.SuiteRunnerWorker.run(SuiteRunnerWorker.java:86)
	at org.testng.TestNG.runSuitesSequentially(TestNG.java:1301)
	at org.testng.TestNG.runSuitesLocally(TestNG.java:1226)
	at org.testng.TestNG.runSuites(TestNG.java:1144)
	at org.testng.TestNG.run(TestNG.java:1115)
	at org.testng.remote.AbstractRemoteTestNG.run(AbstractRemoteTestNG.java:132)
	at org.testng.remote.RemoteTestNG.initAndRun(RemoteTestNG.java:230)
	at org.testng.remote.RemoteTestNG.main(RemoteTestNG.java:76)
]]>
            </full-stacktrace>
          </exception> <!-- java.lang.AssertionError -->
          <reporter-output>
          </reporter-output>
        </test-method> <!-- Order_Certificates -->
        <test-method status="SKIP" signature="User_Login()[pri:0, instance:Sanity_Test.Test_ErrorFix@63753b6d]" name="User_Login" is-config="true" duration-ms="0" started-at="2017-08-03T17:07:20Z" finished-at="2017-08-03T17:07:20Z">
          <reporter-output>
          </reporter-output>
        </test-method> <!-- User_Login -->
        <test-method status="SKIP" signature="Order_Certificates(java.lang.String, java.lang.String)[pri:1, instance:Sanity_Test.Test_ErrorFix@63753b6d]" name="Order_Certificates" duration-ms="0" started-at="2017-08-03T17:07:20Z" data-provider="OrderProduct_Data" finished-at="2017-08-03T17:07:20Z">
          <exception class="java.lang.AssertionError">
            <message>
              <![CDATA[Log Out not visible]]>
            </message>
            <full-stacktrace>
              <![CDATA[java.lang.AssertionError: Log Out not visible
	at org.testng.Assert.fail(Assert.java:93)
	at Sanity_Test.Test_ErrorFix.User_Logout(Test_ErrorFix.java:119)
	at sun.reflect.NativeMethodAccessorImpl.invoke0(Native Method)
	at sun.reflect.NativeMethodAccessorImpl.invoke(NativeMethodAccessorImpl.java:62)
	at sun.reflect.DelegatingMethodAccessorImpl.invoke(DelegatingMethodAccessorImpl.java:43)
	at java.lang.reflect.Method.invoke(Method.java:498)
	at org.testng.internal.MethodInvocationHelper.invokeMethod(MethodInvocationHelper.java:108)
	at org.testng.internal.Invoker.invokeConfigurationMethod(Invoker.java:523)
	at org.testng.internal.Invoker.invokeConfigurations(Invoker.java:224)
	at org.testng.internal.Invoker.invokeMethod(Invoker.java:723)
	at org.testng.internal.Invoker.invokeTestMethod(Invoker.java:869)
	at org.testng.internal.Invoker.invokeTestMethods(Invoker.java:1193)
	at org.testng.internal.TestMethodWorker.invokeTestMethods(TestMethodWorker.java:126)
	at org.testng.internal.TestMethodWorker.run(TestMethodWorker.java:109)
	at org.testng.TestRunner.privateRun(TestRunner.java:744)
	at org.testng.TestRunner.run(TestRunner.java:602)
	at org.testng.SuiteRunner.runTest(SuiteRunner.java:380)
	at org.testng.SuiteRunner.runSequentially(SuiteRunner.java:375)
	at org.testng.SuiteRunner.privateRun(SuiteRunner.java:340)
	at org.testng.SuiteRunner.run(SuiteRunner.java:289)
	at org.testng.SuiteRunnerWorker.runSuite(SuiteRunnerWorker.java:52)
	at org.testng.SuiteRunnerWorker.run(SuiteRunnerWorker.java:86)
	at org.testng.TestNG.runSuitesSequentially(TestNG.java:1301)
	at org.testng.TestNG.runSuitesLocally(TestNG.java:1226)
	at org.testng.TestNG.runSuites(TestNG.java:1144)
	at org.testng.TestNG.run(TestNG.java:1115)
	at org.testng.remote.AbstractRemoteTestNG.run(AbstractRemoteTestNG.java:132)
	at org.testng.remote.RemoteTestNG.initAndRun(RemoteTestNG.java:230)
	at org.testng.remote.RemoteTestNG.main(RemoteTestNG.java:76)
]]>
            </full-stacktrace>
          </exception> <!-- java.lang.AssertionError -->
          <reporter-output>
          </reporter-output>
        </test-method> <!-- Order_Certificates -->
        <test-method status="SKIP" signature="User_Login()[pri:0, instance:Sanity_Test.Test_ErrorFix@63753b6d]" name="User_Login" is-config="true" duration-ms="0" started-at="2017-08-03T17:07:20Z" finished-at="2017-08-03T17:07:20Z">
          <reporter-output>
          </reporter-output>
        </test-method> <!-- User_Login -->
        <test-method status="SKIP" signature="Order_Certificates(java.lang.String, java.lang.String)[pri:1, instance:Sanity_Test.Test_ErrorFix@63753b6d]" name="Order_Certificates" duration-ms="0" started-at="2017-08-03T17:07:20Z" data-provider="OrderProduct_Data" finished-at="2017-08-03T17:07:20Z">
          <exception class="java.lang.AssertionError">
            <message>
              <![CDATA[Log Out not visible]]>
            </message>
            <full-stacktrace>
              <![CDATA[java.lang.AssertionError: Log Out not visible
	at org.testng.Assert.fail(Assert.java:93)
	at Sanity_Test.Test_ErrorFix.User_Logout(Test_ErrorFix.java:119)
	at sun.reflect.NativeMethodAccessorImpl.invoke0(Native Method)
	at sun.reflect.NativeMethodAccessorImpl.invoke(NativeMethodAccessorImpl.java:62)
	at sun.reflect.DelegatingMethodAccessorImpl.invoke(DelegatingMethodAccessorImpl.java:43)
	at java.lang.reflect.Method.invoke(Method.java:498)
	at org.testng.internal.MethodInvocationHelper.invokeMethod(MethodInvocationHelper.java:108)
	at org.testng.internal.Invoker.invokeConfigurationMethod(Invoker.java:523)
	at org.testng.internal.Invoker.invokeConfigurations(Invoker.java:224)
	at org.testng.internal.Invoker.invokeMethod(Invoker.java:723)
	at org.testng.internal.Invoker.invokeTestMethod(Invoker.java:869)
	at org.testng.internal.Invoker.invokeTestMethods(Invoker.java:1193)
	at org.testng.internal.TestMethodWorker.invokeTestMethods(TestMethodWorker.java:126)
	at org.testng.internal.TestMethodWorker.run(TestMethodWorker.java:109)
	at org.testng.TestRunner.privateRun(TestRunner.java:744)
	at org.testng.TestRunner.run(TestRunner.java:602)
	at org.testng.SuiteRunner.runTest(SuiteRunner.java:380)
	at org.testng.SuiteRunner.runSequentially(SuiteRunner.java:375)
	at org.testng.SuiteRunner.privateRun(SuiteRunner.java:340)
	at org.testng.SuiteRunner.run(SuiteRunner.java:289)
	at org.testng.SuiteRunnerWorker.runSuite(SuiteRunnerWorker.java:52)
	at org.testng.SuiteRunnerWorker.run(SuiteRunnerWorker.java:86)
	at org.testng.TestNG.runSuitesSequentially(TestNG.java:1301)
	at org.testng.TestNG.runSuitesLocally(TestNG.java:1226)
	at org.testng.TestNG.runSuites(TestNG.java:1144)
	at org.testng.TestNG.run(TestNG.java:1115)
	at org.testng.remote.AbstractRemoteTestNG.run(AbstractRemoteTestNG.java:132)
	at org.testng.remote.RemoteTestNG.initAndRun(RemoteTestNG.java:230)
	at org.testng.remote.RemoteTestNG.main(RemoteTestNG.java:76)
]]>
            </full-stacktrace>
          </exception> <!-- java.lang.AssertionError -->
          <reporter-output>
          </reporter-output>
        </test-method> <!-- Order_Certificates -->
        <test-method status="SKIP" signature="User_Login()[pri:0, instance:Sanity_Test.Test_ErrorFix@63753b6d]" name="User_Login" is-config="true" duration-ms="0" started-at="2017-08-03T17:07:20Z" finished-at="2017-08-03T17:07:20Z">
          <reporter-output>
          </reporter-output>
        </test-method> <!-- User_Login -->
        <test-method status="SKIP" signature="Order_Certificates(java.lang.String, java.lang.String)[pri:1, instance:Sanity_Test.Test_ErrorFix@63753b6d]" name="Order_Certificates" duration-ms="0" started-at="2017-08-03T17:07:20Z" data-provider="OrderProduct_Data" finished-at="2017-08-03T17:07:20Z">
          <exception class="java.lang.AssertionError">
            <message>
              <![CDATA[Log Out not visible]]>
            </message>
            <full-stacktrace>
              <![CDATA[java.lang.AssertionError: Log Out not visible
	at org.testng.Assert.fail(Assert.java:93)
	at Sanity_Test.Test_ErrorFix.User_Logout(Test_ErrorFix.java:119)
	at sun.reflect.NativeMethodAccessorImpl.invoke0(Native Method)
	at sun.reflect.NativeMethodAccessorImpl.invoke(NativeMethodAccessorImpl.java:62)
	at sun.reflect.DelegatingMethodAccessorImpl.invoke(DelegatingMethodAccessorImpl.java:43)
	at java.lang.reflect.Method.invoke(Method.java:498)
	at org.testng.internal.MethodInvocationHelper.invokeMethod(MethodInvocationHelper.java:108)
	at org.testng.internal.Invoker.invokeConfigurationMethod(Invoker.java:523)
	at org.testng.internal.Invoker.invokeConfigurations(Invoker.java:224)
	at org.testng.internal.Invoker.invokeMethod(Invoker.java:723)
	at org.testng.internal.Invoker.invokeTestMethod(Invoker.java:869)
	at org.testng.internal.Invoker.invokeTestMethods(Invoker.java:1193)
	at org.testng.internal.TestMethodWorker.invokeTestMethods(TestMethodWorker.java:126)
	at org.testng.internal.TestMethodWorker.run(TestMethodWorker.java:109)
	at org.testng.TestRunner.privateRun(TestRunner.java:744)
	at org.testng.TestRunner.run(TestRunner.java:602)
	at org.testng.SuiteRunner.runTest(SuiteRunner.java:380)
	at org.testng.SuiteRunner.runSequentially(SuiteRunner.java:375)
	at org.testng.SuiteRunner.privateRun(SuiteRunner.java:340)
	at org.testng.SuiteRunner.run(SuiteRunner.java:289)
	at org.testng.SuiteRunnerWorker.runSuite(SuiteRunnerWorker.java:52)
	at org.testng.SuiteRunnerWorker.run(SuiteRunnerWorker.java:86)
	at org.testng.TestNG.runSuitesSequentially(TestNG.java:1301)
	at org.testng.TestNG.runSuitesLocally(TestNG.java:1226)
	at org.testng.TestNG.runSuites(TestNG.java:1144)
	at org.testng.TestNG.run(TestNG.java:1115)
	at org.testng.remote.AbstractRemoteTestNG.run(AbstractRemoteTestNG.java:132)
	at org.testng.remote.RemoteTestNG.initAndRun(RemoteTestNG.java:230)
	at org.testng.remote.RemoteTestNG.main(RemoteTestNG.java:76)
]]>
            </full-stacktrace>
          </exception> <!-- java.lang.AssertionError -->
          <reporter-output>
          </reporter-output>
        </test-method> <!-- Order_Certificates -->
        <test-method status="SKIP" signature="User_Login()[pri:0, instance:Sanity_Test.Test_ErrorFix@63753b6d]" name="User_Login" is-config="true" duration-ms="0" started-at="2017-08-03T17:07:20Z" finished-at="2017-08-03T17:07:20Z">
          <reporter-output>
          </reporter-output>
        </test-method> <!-- User_Login -->
        <test-method status="SKIP" signature="Order_Certificates(java.lang.String, java.lang.String)[pri:1, instance:Sanity_Test.Test_ErrorFix@63753b6d]" name="Order_Certificates" duration-ms="0" started-at="2017-08-03T17:07:20Z" data-provider="OrderProduct_Data" finished-at="2017-08-03T17:07:20Z">
          <exception class="java.lang.AssertionError">
            <message>
              <![CDATA[Log Out not visible]]>
            </message>
            <full-stacktrace>
              <![CDATA[java.lang.AssertionError: Log Out not visible
	at org.testng.Assert.fail(Assert.java:93)
	at Sanity_Test.Test_ErrorFix.User_Logout(Test_ErrorFix.java:119)
	at sun.reflect.NativeMethodAccessorImpl.invoke0(Native Method)
	at sun.reflect.NativeMethodAccessorImpl.invoke(NativeMethodAccessorImpl.java:62)
	at sun.reflect.DelegatingMethodAccessorImpl.invoke(DelegatingMethodAccessorImpl.java:43)
	at java.lang.reflect.Method.invoke(Method.java:498)
	at org.testng.internal.MethodInvocationHelper.invokeMethod(MethodInvocationHelper.java:108)
	at org.testng.internal.Invoker.invokeConfigurationMethod(Invoker.java:523)
	at org.testng.internal.Invoker.invokeConfigurations(Invoker.java:224)
	at org.testng.internal.Invoker.invokeMethod(Invoker.java:723)
	at org.testng.internal.Invoker.invokeTestMethod(Invoker.java:869)
	at org.testng.internal.Invoker.invokeTestMethods(Invoker.java:1193)
	at org.testng.internal.TestMethodWorker.invokeTestMethods(TestMethodWorker.java:126)
	at org.testng.internal.TestMethodWorker.run(TestMethodWorker.java:109)
	at org.testng.TestRunner.privateRun(TestRunner.java:744)
	at org.testng.TestRunner.run(TestRunner.java:602)
	at org.testng.SuiteRunner.runTest(SuiteRunner.java:380)
	at org.testng.SuiteRunner.runSequentially(SuiteRunner.java:375)
	at org.testng.SuiteRunner.privateRun(SuiteRunner.java:340)
	at org.testng.SuiteRunner.run(SuiteRunner.java:289)
	at org.testng.SuiteRunnerWorker.runSuite(SuiteRunnerWorker.java:52)
	at org.testng.SuiteRunnerWorker.run(SuiteRunnerWorker.java:86)
	at org.testng.TestNG.runSuitesSequentially(TestNG.java:1301)
	at org.testng.TestNG.runSuitesLocally(TestNG.java:1226)
	at org.testng.TestNG.runSuites(TestNG.java:1144)
	at org.testng.TestNG.run(TestNG.java:1115)
	at org.testng.remote.AbstractRemoteTestNG.run(AbstractRemoteTestNG.java:132)
	at org.testng.remote.RemoteTestNG.initAndRun(RemoteTestNG.java:230)
	at org.testng.remote.RemoteTestNG.main(RemoteTestNG.java:76)
]]>
            </full-stacktrace>
          </exception> <!-- java.lang.AssertionError -->
          <reporter-output>
          </reporter-output>
        </test-method> <!-- Order_Certificates -->
        <test-method status="SKIP" signature="User_Login()[pri:0, instance:Sanity_Test.Test_ErrorFix@63753b6d]" name="User_Login" is-config="true" duration-ms="0" started-at="2017-08-03T17:07:20Z" finished-at="2017-08-03T17:07:20Z">
          <reporter-output>
          </reporter-output>
        </test-method> <!-- User_Login -->
        <test-method status="SKIP" signature="Order_Certificates(java.lang.String, java.lang.String)[pri:1, instance:Sanity_Test.Test_ErrorFix@63753b6d]" name="Order_Certificates" duration-ms="0" started-at="2017-08-03T17:07:20Z" data-provider="OrderProduct_Data" finished-at="2017-08-03T17:07:20Z">
          <exception class="java.lang.AssertionError">
            <message>
              <![CDATA[Log Out not visible]]>
            </message>
            <full-stacktrace>
              <![CDATA[java.lang.AssertionError: Log Out not visible
	at org.testng.Assert.fail(Assert.java:93)
	at Sanity_Test.Test_ErrorFix.User_Logout(Test_ErrorFix.java:119)
	at sun.reflect.NativeMethodAccessorImpl.invoke0(Native Method)
	at sun.reflect.NativeMethodAccessorImpl.invoke(NativeMethodAccessorImpl.java:62)
	at sun.reflect.DelegatingMethodAccessorImpl.invoke(DelegatingMethodAccessorImpl.java:43)
	at java.lang.reflect.Method.invoke(Method.java:498)
	at org.testng.internal.MethodInvocationHelper.invokeMethod(MethodInvocationHelper.java:108)
	at org.testng.internal.Invoker.invokeConfigurationMethod(Invoker.java:523)
	at org.testng.internal.Invoker.invokeConfigurations(Invoker.java:224)
	at org.testng.internal.Invoker.invokeMethod(Invoker.java:723)
	at org.testng.internal.Invoker.invokeTestMethod(Invoker.java:869)
	at org.testng.internal.Invoker.invokeTestMethods(Invoker.java:1193)
	at org.testng.internal.TestMethodWorker.invokeTestMethods(TestMethodWorker.java:126)
	at org.testng.internal.TestMethodWorker.run(TestMethodWorker.java:109)
	at org.testng.TestRunner.privateRun(TestRunner.java:744)
	at org.testng.TestRunner.run(TestRunner.java:602)
	at org.testng.SuiteRunner.runTest(SuiteRunner.java:380)
	at org.testng.SuiteRunner.runSequentially(SuiteRunner.java:375)
	at org.testng.SuiteRunner.privateRun(SuiteRunner.java:340)
	at org.testng.SuiteRunner.run(SuiteRunner.java:289)
	at org.testng.SuiteRunnerWorker.runSuite(SuiteRunnerWorker.java:52)
	at org.testng.SuiteRunnerWorker.run(SuiteRunnerWorker.java:86)
	at org.testng.TestNG.runSuitesSequentially(TestNG.java:1301)
	at org.testng.TestNG.runSuitesLocally(TestNG.java:1226)
	at org.testng.TestNG.runSuites(TestNG.java:1144)
	at org.testng.TestNG.run(TestNG.java:1115)
	at org.testng.remote.AbstractRemoteTestNG.run(AbstractRemoteTestNG.java:132)
	at org.testng.remote.RemoteTestNG.initAndRun(RemoteTestNG.java:230)
	at org.testng.remote.RemoteTestNG.main(RemoteTestNG.java:76)
]]>
            </full-stacktrace>
          </exception> <!-- java.lang.AssertionError -->
          <reporter-output>
          </reporter-output>
        </test-method> <!-- Order_Certificates -->
        <test-method status="SKIP" signature="User_Login()[pri:0, instance:Sanity_Test.Test_ErrorFix@63753b6d]" name="User_Login" is-config="true" duration-ms="0" started-at="2017-08-03T17:07:20Z" finished-at="2017-08-03T17:07:20Z">
          <reporter-output>
          </reporter-output>
        </test-method> <!-- User_Login -->
        <test-method status="SKIP" signature="Order_Certificates(java.lang.String, java.lang.String)[pri:1, instance:Sanity_Test.Test_ErrorFix@63753b6d]" name="Order_Certificates" duration-ms="0" started-at="2017-08-03T17:07:20Z" data-provider="OrderProduct_Data" finished-at="2017-08-03T17:07:20Z">
          <exception class="java.lang.AssertionError">
            <message>
              <![CDATA[Log Out not visible]]>
            </message>
            <full-stacktrace>
              <![CDATA[java.lang.AssertionError: Log Out not visible
	at org.testng.Assert.fail(Assert.java:93)
	at Sanity_Test.Test_ErrorFix.User_Logout(Test_ErrorFix.java:119)
	at sun.reflect.NativeMethodAccessorImpl.invoke0(Native Method)
	at sun.reflect.NativeMethodAccessorImpl.invoke(NativeMethodAccessorImpl.java:62)
	at sun.reflect.DelegatingMethodAccessorImpl.invoke(DelegatingMethodAccessorImpl.java:43)
	at java.lang.reflect.Method.invoke(Method.java:498)
	at org.testng.internal.MethodInvocationHelper.invokeMethod(MethodInvocationHelper.java:108)
	at org.testng.internal.Invoker.invokeConfigurationMethod(Invoker.java:523)
	at org.testng.internal.Invoker.invokeConfigurations(Invoker.java:224)
	at org.testng.internal.Invoker.invokeMethod(Invoker.java:723)
	at org.testng.internal.Invoker.invokeTestMethod(Invoker.java:869)
	at org.testng.internal.Invoker.invokeTestMethods(Invoker.java:1193)
	at org.testng.internal.TestMethodWorker.invokeTestMethods(TestMethodWorker.java:126)
	at org.testng.internal.TestMethodWorker.run(TestMethodWorker.java:109)
	at org.testng.TestRunner.privateRun(TestRunner.java:744)
	at org.testng.TestRunner.run(TestRunner.java:602)
	at org.testng.SuiteRunner.runTest(SuiteRunner.java:380)
	at org.testng.SuiteRunner.runSequentially(SuiteRunner.java:375)
	at org.testng.SuiteRunner.privateRun(SuiteRunner.java:340)
	at org.testng.SuiteRunner.run(SuiteRunner.java:289)
	at org.testng.SuiteRunnerWorker.runSuite(SuiteRunnerWorker.java:52)
	at org.testng.SuiteRunnerWorker.run(SuiteRunnerWorker.java:86)
	at org.testng.TestNG.runSuitesSequentially(TestNG.java:1301)
	at org.testng.TestNG.runSuitesLocally(TestNG.java:1226)
	at org.testng.TestNG.runSuites(TestNG.java:1144)
	at org.testng.TestNG.run(TestNG.java:1115)
	at org.testng.remote.AbstractRemoteTestNG.run(AbstractRemoteTestNG.java:132)
	at org.testng.remote.RemoteTestNG.initAndRun(RemoteTestNG.java:230)
	at org.testng.remote.RemoteTestNG.main(RemoteTestNG.java:76)
]]>
            </full-stacktrace>
          </exception> <!-- java.lang.AssertionError -->
          <reporter-output>
          </reporter-output>
        </test-method> <!-- Order_Certificates -->
        <test-method status="SKIP" signature="User_Login()[pri:0, instance:Sanity_Test.Test_ErrorFix@63753b6d]" name="User_Login" is-config="true" duration-ms="0" started-at="2017-08-03T17:07:20Z" finished-at="2017-08-03T17:07:20Z">
          <reporter-output>
          </reporter-output>
        </test-method> <!-- User_Login -->
        <test-method status="SKIP" signature="Order_Certificates(java.lang.String, java.lang.String)[pri:1, instance:Sanity_Test.Test_ErrorFix@63753b6d]" name="Order_Certificates" duration-ms="0" started-at="2017-08-03T17:07:20Z" data-provider="OrderProduct_Data" finished-at="2017-08-03T17:07:20Z">
          <exception class="java.lang.AssertionError">
            <message>
              <![CDATA[Log Out not visible]]>
            </message>
            <full-stacktrace>
              <![CDATA[java.lang.AssertionError: Log Out not visible
	at org.testng.Assert.fail(Assert.java:93)
	at Sanity_Test.Test_ErrorFix.User_Logout(Test_ErrorFix.java:119)
	at sun.reflect.NativeMethodAccessorImpl.invoke0(Native Method)
	at sun.reflect.NativeMethodAccessorImpl.invoke(NativeMethodAccessorImpl.java:62)
	at sun.reflect.DelegatingMethodAccessorImpl.invoke(DelegatingMethodAccessorImpl.java:43)
	at java.lang.reflect.Method.invoke(Method.java:498)
	at org.testng.internal.MethodInvocationHelper.invokeMethod(MethodInvocationHelper.java:108)
	at org.testng.internal.Invoker.invokeConfigurationMethod(Invoker.java:523)
	at org.testng.internal.Invoker.invokeConfigurations(Invoker.java:224)
	at org.testng.internal.Invoker.invokeMethod(Invoker.java:723)
	at org.testng.internal.Invoker.invokeTestMethod(Invoker.java:869)
	at org.testng.internal.Invoker.invokeTestMethods(Invoker.java:1193)
	at org.testng.internal.TestMethodWorker.invokeTestMethods(TestMethodWorker.java:126)
	at org.testng.internal.TestMethodWorker.run(TestMethodWorker.java:109)
	at org.testng.TestRunner.privateRun(TestRunner.java:744)
	at org.testng.TestRunner.run(TestRunner.java:602)
	at org.testng.SuiteRunner.runTest(SuiteRunner.java:380)
	at org.testng.SuiteRunner.runSequentially(SuiteRunner.java:375)
	at org.testng.SuiteRunner.privateRun(SuiteRunner.java:340)
	at org.testng.SuiteRunner.run(SuiteRunner.java:289)
	at org.testng.SuiteRunnerWorker.runSuite(SuiteRunnerWorker.java:52)
	at org.testng.SuiteRunnerWorker.run(SuiteRunnerWorker.java:86)
	at org.testng.TestNG.runSuitesSequentially(TestNG.java:1301)
	at org.testng.TestNG.runSuitesLocally(TestNG.java:1226)
	at org.testng.TestNG.runSuites(TestNG.java:1144)
	at org.testng.TestNG.run(TestNG.java:1115)
	at org.testng.remote.AbstractRemoteTestNG.run(AbstractRemoteTestNG.java:132)
	at org.testng.remote.RemoteTestNG.initAndRun(RemoteTestNG.java:230)
	at org.testng.remote.RemoteTestNG.main(RemoteTestNG.java:76)
]]>
            </full-stacktrace>
          </exception> <!-- java.lang.AssertionError -->
          <reporter-output>
          </reporter-output>
        </test-method> <!-- Order_Certificates -->
        <test-method status="SKIP" signature="User_Login()[pri:0, instance:Sanity_Test.Test_ErrorFix@63753b6d]" name="User_Login" is-config="true" duration-ms="0" started-at="2017-08-03T17:07:20Z" finished-at="2017-08-03T17:07:20Z">
          <reporter-output>
          </reporter-output>
        </test-method> <!-- User_Login -->
        <test-method status="SKIP" signature="Order_Certificates(java.lang.String, java.lang.String)[pri:1, instance:Sanity_Test.Test_ErrorFix@63753b6d]" name="Order_Certificates" duration-ms="0" started-at="2017-08-03T17:07:20Z" data-provider="OrderProduct_Data" finished-at="2017-08-03T17:07:20Z">
          <exception class="java.lang.AssertionError">
            <message>
              <![CDATA[Log Out not visible]]>
            </message>
            <full-stacktrace>
              <![CDATA[java.lang.AssertionError: Log Out not visible
	at org.testng.Assert.fail(Assert.java:93)
	at Sanity_Test.Test_ErrorFix.User_Logout(Test_ErrorFix.java:119)
	at sun.reflect.NativeMethodAccessorImpl.invoke0(Native Method)
	at sun.reflect.NativeMethodAccessorImpl.invoke(NativeMethodAccessorImpl.java:62)
	at sun.reflect.DelegatingMethodAccessorImpl.invoke(DelegatingMethodAccessorImpl.java:43)
	at java.lang.reflect.Method.invoke(Method.java:498)
	at org.testng.internal.MethodInvocationHelper.invokeMethod(MethodInvocationHelper.java:108)
	at org.testng.internal.Invoker.invokeConfigurationMethod(Invoker.java:523)
	at org.testng.internal.Invoker.invokeConfigurations(Invoker.java:224)
	at org.testng.internal.Invoker.invokeMethod(Invoker.java:723)
	at org.testng.internal.Invoker.invokeTestMethod(Invoker.java:869)
	at org.testng.internal.Invoker.invokeTestMethods(Invoker.java:1193)
	at org.testng.internal.TestMethodWorker.invokeTestMethods(TestMethodWorker.java:126)
	at org.testng.internal.TestMethodWorker.run(TestMethodWorker.java:109)
	at org.testng.TestRunner.privateRun(TestRunner.java:744)
	at org.testng.TestRunner.run(TestRunner.java:602)
	at org.testng.SuiteRunner.runTest(SuiteRunner.java:380)
	at org.testng.SuiteRunner.runSequentially(SuiteRunner.java:375)
	at org.testng.SuiteRunner.privateRun(SuiteRunner.java:340)
	at org.testng.SuiteRunner.run(SuiteRunner.java:289)
	at org.testng.SuiteRunnerWorker.runSuite(SuiteRunnerWorker.java:52)
	at org.testng.SuiteRunnerWorker.run(SuiteRunnerWorker.java:86)
	at org.testng.TestNG.runSuitesSequentially(TestNG.java:1301)
	at org.testng.TestNG.runSuitesLocally(TestNG.java:1226)
	at org.testng.TestNG.runSuites(TestNG.java:1144)
	at org.testng.TestNG.run(TestNG.java:1115)
	at org.testng.remote.AbstractRemoteTestNG.run(AbstractRemoteTestNG.java:132)
	at org.testng.remote.RemoteTestNG.initAndRun(RemoteTestNG.java:230)
	at org.testng.remote.RemoteTestNG.main(RemoteTestNG.java:76)
]]>
            </full-stacktrace>
          </exception> <!-- java.lang.AssertionError -->
          <reporter-output>
          </reporter-output>
        </test-method> <!-- Order_Certificates -->
        <test-method status="SKIP" signature="User_Login()[pri:0, instance:Sanity_Test.Test_ErrorFix@63753b6d]" name="User_Login" is-config="true" duration-ms="0" started-at="2017-08-03T17:07:20Z" finished-at="2017-08-03T17:07:20Z">
          <reporter-output>
          </reporter-output>
        </test-method> <!-- User_Login -->
        <test-method status="SKIP" signature="Order_Certificates(java.lang.String, java.lang.String)[pri:1, instance:Sanity_Test.Test_ErrorFix@63753b6d]" name="Order_Certificates" duration-ms="0" started-at="2017-08-03T17:07:20Z" data-provider="OrderProduct_Data" finished-at="2017-08-03T17:07:20Z">
          <exception class="java.lang.AssertionError">
            <message>
              <![CDATA[Log Out not visible]]>
            </message>
            <full-stacktrace>
              <![CDATA[java.lang.AssertionError: Log Out not visible
	at org.testng.Assert.fail(Assert.java:93)
	at Sanity_Test.Test_ErrorFix.User_Logout(Test_ErrorFix.java:119)
	at sun.reflect.NativeMethodAccessorImpl.invoke0(Native Method)
	at sun.reflect.NativeMethodAccessorImpl.invoke(NativeMethodAccessorImpl.java:62)
	at sun.reflect.DelegatingMethodAccessorImpl.invoke(DelegatingMethodAccessorImpl.java:43)
	at java.lang.reflect.Method.invoke(Method.java:498)
	at org.testng.internal.MethodInvocationHelper.invokeMethod(MethodInvocationHelper.java:108)
	at org.testng.internal.Invoker.invokeConfigurationMethod(Invoker.java:523)
	at org.testng.internal.Invoker.invokeConfigurations(Invoker.java:224)
	at org.testng.internal.Invoker.invokeMethod(Invoker.java:723)
	at org.testng.internal.Invoker.invokeTestMethod(Invoker.java:869)
	at org.testng.internal.Invoker.invokeTestMethods(Invoker.java:1193)
	at org.testng.internal.TestMethodWorker.invokeTestMethods(TestMethodWorker.java:126)
	at org.testng.internal.TestMethodWorker.run(TestMethodWorker.java:109)
	at org.testng.TestRunner.privateRun(TestRunner.java:744)
	at org.testng.TestRunner.run(TestRunner.java:602)
	at org.testng.SuiteRunner.runTest(SuiteRunner.java:380)
	at org.testng.SuiteRunner.runSequentially(SuiteRunner.java:375)
	at org.testng.SuiteRunner.privateRun(SuiteRunner.java:340)
	at org.testng.SuiteRunner.run(SuiteRunner.java:289)
	at org.testng.SuiteRunnerWorker.runSuite(SuiteRunnerWorker.java:52)
	at org.testng.SuiteRunnerWorker.run(SuiteRunnerWorker.java:86)
	at org.testng.TestNG.runSuitesSequentially(TestNG.java:1301)
	at org.testng.TestNG.runSuitesLocally(TestNG.java:1226)
	at org.testng.TestNG.runSuites(TestNG.java:1144)
	at org.testng.TestNG.run(TestNG.java:1115)
	at org.testng.remote.AbstractRemoteTestNG.run(AbstractRemoteTestNG.java:132)
	at org.testng.remote.RemoteTestNG.initAndRun(RemoteTestNG.java:230)
	at org.testng.remote.RemoteTestNG.main(RemoteTestNG.java:76)
]]>
            </full-stacktrace>
          </exception> <!-- java.lang.AssertionError -->
          <reporter-output>
          </reporter-output>
        </test-method> <!-- Order_Certificates -->
        <test-method status="SKIP" signature="User_Login()[pri:0, instance:Sanity_Test.Test_ErrorFix@63753b6d]" name="User_Login" is-config="true" duration-ms="0" started-at="2017-08-03T17:07:20Z" finished-at="2017-08-03T17:07:20Z">
          <reporter-output>
          </reporter-output>
        </test-method> <!-- User_Login -->
        <test-method status="SKIP" signature="Order_Certificates(java.lang.String, java.lang.String)[pri:1, instance:Sanity_Test.Test_ErrorFix@63753b6d]" name="Order_Certificates" duration-ms="0" started-at="2017-08-03T17:07:20Z" data-provider="OrderProduct_Data" finished-at="2017-08-03T17:07:20Z">
          <exception class="java.lang.AssertionError">
            <message>
              <![CDATA[Log Out not visible]]>
            </message>
            <full-stacktrace>
              <![CDATA[java.lang.AssertionError: Log Out not visible
	at org.testng.Assert.fail(Assert.java:93)
	at Sanity_Test.Test_ErrorFix.User_Logout(Test_ErrorFix.java:119)
	at sun.reflect.NativeMethodAccessorImpl.invoke0(Native Method)
	at sun.reflect.NativeMethodAccessorImpl.invoke(NativeMethodAccessorImpl.java:62)
	at sun.reflect.DelegatingMethodAccessorImpl.invoke(DelegatingMethodAccessorImpl.java:43)
	at java.lang.reflect.Method.invoke(Method.java:498)
	at org.testng.internal.MethodInvocationHelper.invokeMethod(MethodInvocationHelper.java:108)
	at org.testng.internal.Invoker.invokeConfigurationMethod(Invoker.java:523)
	at org.testng.internal.Invoker.invokeConfigurations(Invoker.java:224)
	at org.testng.internal.Invoker.invokeMethod(Invoker.java:723)
	at org.testng.internal.Invoker.invokeTestMethod(Invoker.java:869)
	at org.testng.internal.Invoker.invokeTestMethods(Invoker.java:1193)
	at org.testng.internal.TestMethodWorker.invokeTestMethods(TestMethodWorker.java:126)
	at org.testng.internal.TestMethodWorker.run(TestMethodWorker.java:109)
	at org.testng.TestRunner.privateRun(TestRunner.java:744)
	at org.testng.TestRunner.run(TestRunner.java:602)
	at org.testng.SuiteRunner.runTest(SuiteRunner.java:380)
	at org.testng.SuiteRunner.runSequentially(SuiteRunner.java:375)
	at org.testng.SuiteRunner.privateRun(SuiteRunner.java:340)
	at org.testng.SuiteRunner.run(SuiteRunner.java:289)
	at org.testng.SuiteRunnerWorker.runSuite(SuiteRunnerWorker.java:52)
	at org.testng.SuiteRunnerWorker.run(SuiteRunnerWorker.java:86)
	at org.testng.TestNG.runSuitesSequentially(TestNG.java:1301)
	at org.testng.TestNG.runSuitesLocally(TestNG.java:1226)
	at org.testng.TestNG.runSuites(TestNG.java:1144)
	at org.testng.TestNG.run(TestNG.java:1115)
	at org.testng.remote.AbstractRemoteTestNG.run(AbstractRemoteTestNG.java:132)
	at org.testng.remote.RemoteTestNG.initAndRun(RemoteTestNG.java:230)
	at org.testng.remote.RemoteTestNG.main(RemoteTestNG.java:76)
]]>
            </full-stacktrace>
          </exception> <!-- java.lang.AssertionError -->
          <reporter-output>
          </reporter-output>
        </test-method> <!-- Order_Certificates -->
        <test-method status="SKIP" signature="User_Login()[pri:0, instance:Sanity_Test.Test_ErrorFix@63753b6d]" name="User_Login" is-config="true" duration-ms="0" started-at="2017-08-03T17:07:20Z" finished-at="2017-08-03T17:07:20Z">
          <reporter-output>
          </reporter-output>
        </test-method> <!-- User_Login -->
        <test-method status="SKIP" signature="Order_Certificates(java.lang.String, java.lang.String)[pri:1, instance:Sanity_Test.Test_ErrorFix@63753b6d]" name="Order_Certificates" duration-ms="0" started-at="2017-08-03T17:07:20Z" data-provider="OrderProduct_Data" finished-at="2017-08-03T17:07:20Z">
          <exception class="java.lang.AssertionError">
            <message>
              <![CDATA[Log Out not visible]]>
            </message>
            <full-stacktrace>
              <![CDATA[java.lang.AssertionError: Log Out not visible
	at org.testng.Assert.fail(Assert.java:93)
	at Sanity_Test.Test_ErrorFix.User_Logout(Test_ErrorFix.java:119)
	at sun.reflect.NativeMethodAccessorImpl.invoke0(Native Method)
	at sun.reflect.NativeMethodAccessorImpl.invoke(NativeMethodAccessorImpl.java:62)
	at sun.reflect.DelegatingMethodAccessorImpl.invoke(DelegatingMethodAccessorImpl.java:43)
	at java.lang.reflect.Method.invoke(Method.java:498)
	at org.testng.internal.MethodInvocationHelper.invokeMethod(MethodInvocationHelper.java:108)
	at org.testng.internal.Invoker.invokeConfigurationMethod(Invoker.java:523)
	at org.testng.internal.Invoker.invokeConfigurations(Invoker.java:224)
	at org.testng.internal.Invoker.invokeMethod(Invoker.java:723)
	at org.testng.internal.Invoker.invokeTestMethod(Invoker.java:869)
	at org.testng.internal.Invoker.invokeTestMethods(Invoker.java:1193)
	at org.testng.internal.TestMethodWorker.invokeTestMethods(TestMethodWorker.java:126)
	at org.testng.internal.TestMethodWorker.run(TestMethodWorker.java:109)
	at org.testng.TestRunner.privateRun(TestRunner.java:744)
	at org.testng.TestRunner.run(TestRunner.java:602)
	at org.testng.SuiteRunner.runTest(SuiteRunner.java:380)
	at org.testng.SuiteRunner.runSequentially(SuiteRunner.java:375)
	at org.testng.SuiteRunner.privateRun(SuiteRunner.java:340)
	at org.testng.SuiteRunner.run(SuiteRunner.java:289)
	at org.testng.SuiteRunnerWorker.runSuite(SuiteRunnerWorker.java:52)
	at org.testng.SuiteRunnerWorker.run(SuiteRunnerWorker.java:86)
	at org.testng.TestNG.runSuitesSequentially(TestNG.java:1301)
	at org.testng.TestNG.runSuitesLocally(TestNG.java:1226)
	at org.testng.TestNG.runSuites(TestNG.java:1144)
	at org.testng.TestNG.run(TestNG.java:1115)
	at org.testng.remote.AbstractRemoteTestNG.run(AbstractRemoteTestNG.java:132)
	at org.testng.remote.RemoteTestNG.initAndRun(RemoteTestNG.java:230)
	at org.testng.remote.RemoteTestNG.main(RemoteTestNG.java:76)
]]>
            </full-stacktrace>
          </exception> <!-- java.lang.AssertionError -->
          <reporter-output>
          </reporter-output>
        </test-method> <!-- Order_Certificates -->
        <test-method status="SKIP" signature="User_Login()[pri:0, instance:Sanity_Test.Test_ErrorFix@63753b6d]" name="User_Login" is-config="true" duration-ms="0" started-at="2017-08-03T17:07:20Z" finished-at="2017-08-03T17:07:20Z">
          <reporter-output>
          </reporter-output>
        </test-method> <!-- User_Login -->
        <test-method status="SKIP" signature="Order_Certificates(java.lang.String, java.lang.String)[pri:1, instance:Sanity_Test.Test_ErrorFix@63753b6d]" name="Order_Certificates" duration-ms="0" started-at="2017-08-03T17:07:20Z" data-provider="OrderProduct_Data" finished-at="2017-08-03T17:07:20Z">
          <exception class="java.lang.AssertionError">
            <message>
              <![CDATA[Log Out not visible]]>
            </message>
            <full-stacktrace>
              <![CDATA[java.lang.AssertionError: Log Out not visible
	at org.testng.Assert.fail(Assert.java:93)
	at Sanity_Test.Test_ErrorFix.User_Logout(Test_ErrorFix.java:119)
	at sun.reflect.NativeMethodAccessorImpl.invoke0(Native Method)
	at sun.reflect.NativeMethodAccessorImpl.invoke(NativeMethodAccessorImpl.java:62)
	at sun.reflect.DelegatingMethodAccessorImpl.invoke(DelegatingMethodAccessorImpl.java:43)
	at java.lang.reflect.Method.invoke(Method.java:498)
	at org.testng.internal.MethodInvocationHelper.invokeMethod(MethodInvocationHelper.java:108)
	at org.testng.internal.Invoker.invokeConfigurationMethod(Invoker.java:523)
	at org.testng.internal.Invoker.invokeConfigurations(Invoker.java:224)
	at org.testng.internal.Invoker.invokeMethod(Invoker.java:723)
	at org.testng.internal.Invoker.invokeTestMethod(Invoker.java:869)
	at org.testng.internal.Invoker.invokeTestMethods(Invoker.java:1193)
	at org.testng.internal.TestMethodWorker.invokeTestMethods(TestMethodWorker.java:126)
	at org.testng.internal.TestMethodWorker.run(TestMethodWorker.java:109)
	at org.testng.TestRunner.privateRun(TestRunner.java:744)
	at org.testng.TestRunner.run(TestRunner.java:602)
	at org.testng.SuiteRunner.runTest(SuiteRunner.java:380)
	at org.testng.SuiteRunner.runSequentially(SuiteRunner.java:375)
	at org.testng.SuiteRunner.privateRun(SuiteRunner.java:340)
	at org.testng.SuiteRunner.run(SuiteRunner.java:289)
	at org.testng.SuiteRunnerWorker.runSuite(SuiteRunnerWorker.java:52)
	at org.testng.SuiteRunnerWorker.run(SuiteRunnerWorker.java:86)
	at org.testng.TestNG.runSuitesSequentially(TestNG.java:1301)
	at org.testng.TestNG.runSuitesLocally(TestNG.java:1226)
	at org.testng.TestNG.runSuites(TestNG.java:1144)
	at org.testng.TestNG.run(TestNG.java:1115)
	at org.testng.remote.AbstractRemoteTestNG.run(AbstractRemoteTestNG.java:132)
	at org.testng.remote.RemoteTestNG.initAndRun(RemoteTestNG.java:230)
	at org.testng.remote.RemoteTestNG.main(RemoteTestNG.java:76)
]]>
            </full-stacktrace>
          </exception> <!-- java.lang.AssertionError -->
          <reporter-output>
          </reporter-output>
        </test-method> <!-- Order_Certificates -->
        <test-method status="SKIP" signature="User_Login()[pri:0, instance:Sanity_Test.Test_ErrorFix@63753b6d]" name="User_Login" is-config="true" duration-ms="0" started-at="2017-08-03T17:07:20Z" finished-at="2017-08-03T17:07:20Z">
          <reporter-output>
          </reporter-output>
        </test-method> <!-- User_Login -->
        <test-method status="SKIP" signature="Order_Certificates(java.lang.String, java.lang.String)[pri:1, instance:Sanity_Test.Test_ErrorFix@63753b6d]" name="Order_Certificates" duration-ms="0" started-at="2017-08-03T17:07:20Z" data-provider="OrderProduct_Data" finished-at="2017-08-03T17:07:20Z">
          <exception class="java.lang.AssertionError">
            <message>
              <![CDATA[Log Out not visible]]>
            </message>
            <full-stacktrace>
              <![CDATA[java.lang.AssertionError: Log Out not visible
	at org.testng.Assert.fail(Assert.java:93)
	at Sanity_Test.Test_ErrorFix.User_Logout(Test_ErrorFix.java:119)
	at sun.reflect.NativeMethodAccessorImpl.invoke0(Native Method)
	at sun.reflect.NativeMethodAccessorImpl.invoke(NativeMethodAccessorImpl.java:62)
	at sun.reflect.DelegatingMethodAccessorImpl.invoke(DelegatingMethodAccessorImpl.java:43)
	at java.lang.reflect.Method.invoke(Method.java:498)
	at org.testng.internal.MethodInvocationHelper.invokeMethod(MethodInvocationHelper.java:108)
	at org.testng.internal.Invoker.invokeConfigurationMethod(Invoker.java:523)
	at org.testng.internal.Invoker.invokeConfigurations(Invoker.java:224)
	at org.testng.internal.Invoker.invokeMethod(Invoker.java:723)
	at org.testng.internal.Invoker.invokeTestMethod(Invoker.java:869)
	at org.testng.internal.Invoker.invokeTestMethods(Invoker.java:1193)
	at org.testng.internal.TestMethodWorker.invokeTestMethods(TestMethodWorker.java:126)
	at org.testng.internal.TestMethodWorker.run(TestMethodWorker.java:109)
	at org.testng.TestRunner.privateRun(TestRunner.java:744)
	at org.testng.TestRunner.run(TestRunner.java:602)
	at org.testng.SuiteRunner.runTest(SuiteRunner.java:380)
	at org.testng.SuiteRunner.runSequentially(SuiteRunner.java:375)
	at org.testng.SuiteRunner.privateRun(SuiteRunner.java:340)
	at org.testng.SuiteRunner.run(SuiteRunner.java:289)
	at org.testng.SuiteRunnerWorker.runSuite(SuiteRunnerWorker.java:52)
	at org.testng.SuiteRunnerWorker.run(SuiteRunnerWorker.java:86)
	at org.testng.TestNG.runSuitesSequentially(TestNG.java:1301)
	at org.testng.TestNG.runSuitesLocally(TestNG.java:1226)
	at org.testng.TestNG.runSuites(TestNG.java:1144)
	at org.testng.TestNG.run(TestNG.java:1115)
	at org.testng.remote.AbstractRemoteTestNG.run(AbstractRemoteTestNG.java:132)
	at org.testng.remote.RemoteTestNG.initAndRun(RemoteTestNG.java:230)
	at org.testng.remote.RemoteTestNG.main(RemoteTestNG.java:76)
]]>
            </full-stacktrace>
          </exception> <!-- java.lang.AssertionError -->
          <reporter-output>
          </reporter-output>
        </test-method> <!-- Order_Certificates -->
        <test-method status="SKIP" signature="User_Login()[pri:0, instance:Sanity_Test.Test_ErrorFix@63753b6d]" name="User_Login" is-config="true" duration-ms="0" started-at="2017-08-03T17:07:20Z" finished-at="2017-08-03T17:07:20Z">
          <reporter-output>
          </reporter-output>
        </test-method> <!-- User_Login -->
        <test-method status="SKIP" signature="Order_Certificates(java.lang.String, java.lang.String)[pri:1, instance:Sanity_Test.Test_ErrorFix@63753b6d]" name="Order_Certificates" duration-ms="0" started-at="2017-08-03T17:07:20Z" data-provider="OrderProduct_Data" finished-at="2017-08-03T17:07:20Z">
          <exception class="java.lang.AssertionError">
            <message>
              <![CDATA[Log Out not visible]]>
            </message>
            <full-stacktrace>
              <![CDATA[java.lang.AssertionError: Log Out not visible
	at org.testng.Assert.fail(Assert.java:93)
	at Sanity_Test.Test_ErrorFix.User_Logout(Test_ErrorFix.java:119)
	at sun.reflect.NativeMethodAccessorImpl.invoke0(Native Method)
	at sun.reflect.NativeMethodAccessorImpl.invoke(NativeMethodAccessorImpl.java:62)
	at sun.reflect.DelegatingMethodAccessorImpl.invoke(DelegatingMethodAccessorImpl.java:43)
	at java.lang.reflect.Method.invoke(Method.java:498)
	at org.testng.internal.MethodInvocationHelper.invokeMethod(MethodInvocationHelper.java:108)
	at org.testng.internal.Invoker.invokeConfigurationMethod(Invoker.java:523)
	at org.testng.internal.Invoker.invokeConfigurations(Invoker.java:224)
	at org.testng.internal.Invoker.invokeMethod(Invoker.java:723)
	at org.testng.internal.Invoker.invokeTestMethod(Invoker.java:869)
	at org.testng.internal.Invoker.invokeTestMethods(Invoker.java:1193)
	at org.testng.internal.TestMethodWorker.invokeTestMethods(TestMethodWorker.java:126)
	at org.testng.internal.TestMethodWorker.run(TestMethodWorker.java:109)
	at org.testng.TestRunner.privateRun(TestRunner.java:744)
	at org.testng.TestRunner.run(TestRunner.java:602)
	at org.testng.SuiteRunner.runTest(SuiteRunner.java:380)
	at org.testng.SuiteRunner.runSequentially(SuiteRunner.java:375)
	at org.testng.SuiteRunner.privateRun(SuiteRunner.java:340)
	at org.testng.SuiteRunner.run(SuiteRunner.java:289)
	at org.testng.SuiteRunnerWorker.runSuite(SuiteRunnerWorker.java:52)
	at org.testng.SuiteRunnerWorker.run(SuiteRunnerWorker.java:86)
	at org.testng.TestNG.runSuitesSequentially(TestNG.java:1301)
	at org.testng.TestNG.runSuitesLocally(TestNG.java:1226)
	at org.testng.TestNG.runSuites(TestNG.java:1144)
	at org.testng.TestNG.run(TestNG.java:1115)
	at org.testng.remote.AbstractRemoteTestNG.run(AbstractRemoteTestNG.java:132)
	at org.testng.remote.RemoteTestNG.initAndRun(RemoteTestNG.java:230)
	at org.testng.remote.RemoteTestNG.main(RemoteTestNG.java:76)
]]>
            </full-stacktrace>
          </exception> <!-- java.lang.AssertionError -->
          <reporter-output>
          </reporter-output>
        </test-method> <!-- Order_Certificates -->
        <test-method status="SKIP" signature="User_Login()[pri:0, instance:Sanity_Test.Test_ErrorFix@63753b6d]" name="User_Login" is-config="true" duration-ms="0" started-at="2017-08-03T17:07:20Z" finished-at="2017-08-03T17:07:20Z">
          <reporter-output>
          </reporter-output>
        </test-method> <!-- User_Login -->
        <test-method status="SKIP" signature="Order_Certificates(java.lang.String, java.lang.String)[pri:1, instance:Sanity_Test.Test_ErrorFix@63753b6d]" name="Order_Certificates" duration-ms="0" started-at="2017-08-03T17:07:20Z" data-provider="OrderProduct_Data" finished-at="2017-08-03T17:07:20Z">
          <exception class="java.lang.AssertionError">
            <message>
              <![CDATA[Log Out not visible]]>
            </message>
            <full-stacktrace>
              <![CDATA[java.lang.AssertionError: Log Out not visible
	at org.testng.Assert.fail(Assert.java:93)
	at Sanity_Test.Test_ErrorFix.User_Logout(Test_ErrorFix.java:119)
	at sun.reflect.NativeMethodAccessorImpl.invoke0(Native Method)
	at sun.reflect.NativeMethodAccessorImpl.invoke(NativeMethodAccessorImpl.java:62)
	at sun.reflect.DelegatingMethodAccessorImpl.invoke(DelegatingMethodAccessorImpl.java:43)
	at java.lang.reflect.Method.invoke(Method.java:498)
	at org.testng.internal.MethodInvocationHelper.invokeMethod(MethodInvocationHelper.java:108)
	at org.testng.internal.Invoker.invokeConfigurationMethod(Invoker.java:523)
	at org.testng.internal.Invoker.invokeConfigurations(Invoker.java:224)
	at org.testng.internal.Invoker.invokeMethod(Invoker.java:723)
	at org.testng.internal.Invoker.invokeTestMethod(Invoker.java:869)
	at org.testng.internal.Invoker.invokeTestMethods(Invoker.java:1193)
	at org.testng.internal.TestMethodWorker.invokeTestMethods(TestMethodWorker.java:126)
	at org.testng.internal.TestMethodWorker.run(TestMethodWorker.java:109)
	at org.testng.TestRunner.privateRun(TestRunner.java:744)
	at org.testng.TestRunner.run(TestRunner.java:602)
	at org.testng.SuiteRunner.runTest(SuiteRunner.java:380)
	at org.testng.SuiteRunner.runSequentially(SuiteRunner.java:375)
	at org.testng.SuiteRunner.privateRun(SuiteRunner.java:340)
	at org.testng.SuiteRunner.run(SuiteRunner.java:289)
	at org.testng.SuiteRunnerWorker.runSuite(SuiteRunnerWorker.java:52)
	at org.testng.SuiteRunnerWorker.run(SuiteRunnerWorker.java:86)
	at org.testng.TestNG.runSuitesSequentially(TestNG.java:1301)
	at org.testng.TestNG.runSuitesLocally(TestNG.java:1226)
	at org.testng.TestNG.runSuites(TestNG.java:1144)
	at org.testng.TestNG.run(TestNG.java:1115)
	at org.testng.remote.AbstractRemoteTestNG.run(AbstractRemoteTestNG.java:132)
	at org.testng.remote.RemoteTestNG.initAndRun(RemoteTestNG.java:230)
	at org.testng.remote.RemoteTestNG.main(RemoteTestNG.java:76)
]]>
            </full-stacktrace>
          </exception> <!-- java.lang.AssertionError -->
          <reporter-output>
          </reporter-output>
        </test-method> <!-- Order_Certificates -->
        <test-method status="SKIP" signature="User_Login()[pri:0, instance:Sanity_Test.Test_ErrorFix@63753b6d]" name="User_Login" is-config="true" duration-ms="0" started-at="2017-08-03T17:07:20Z" finished-at="2017-08-03T17:07:20Z">
          <reporter-output>
          </reporter-output>
        </test-method> <!-- User_Login -->
        <test-method status="SKIP" signature="Order_Certificates(java.lang.String, java.lang.String)[pri:1, instance:Sanity_Test.Test_ErrorFix@63753b6d]" name="Order_Certificates" duration-ms="0" started-at="2017-08-03T17:07:20Z" data-provider="OrderProduct_Data" finished-at="2017-08-03T17:07:20Z">
          <exception class="java.lang.AssertionError">
            <message>
              <![CDATA[Log Out not visible]]>
            </message>
            <full-stacktrace>
              <![CDATA[java.lang.AssertionError: Log Out not visible
	at org.testng.Assert.fail(Assert.java:93)
	at Sanity_Test.Test_ErrorFix.User_Logout(Test_ErrorFix.java:119)
	at sun.reflect.NativeMethodAccessorImpl.invoke0(Native Method)
	at sun.reflect.NativeMethodAccessorImpl.invoke(NativeMethodAccessorImpl.java:62)
	at sun.reflect.DelegatingMethodAccessorImpl.invoke(DelegatingMethodAccessorImpl.java:43)
	at java.lang.reflect.Method.invoke(Method.java:498)
	at org.testng.internal.MethodInvocationHelper.invokeMethod(MethodInvocationHelper.java:108)
	at org.testng.internal.Invoker.invokeConfigurationMethod(Invoker.java:523)
	at org.testng.internal.Invoker.invokeConfigurations(Invoker.java:224)
	at org.testng.internal.Invoker.invokeMethod(Invoker.java:723)
	at org.testng.internal.Invoker.invokeTestMethod(Invoker.java:869)
	at org.testng.internal.Invoker.invokeTestMethods(Invoker.java:1193)
	at org.testng.internal.TestMethodWorker.invokeTestMethods(TestMethodWorker.java:126)
	at org.testng.internal.TestMethodWorker.run(TestMethodWorker.java:109)
	at org.testng.TestRunner.privateRun(TestRunner.java:744)
	at org.testng.TestRunner.run(TestRunner.java:602)
	at org.testng.SuiteRunner.runTest(SuiteRunner.java:380)
	at org.testng.SuiteRunner.runSequentially(SuiteRunner.java:375)
	at org.testng.SuiteRunner.privateRun(SuiteRunner.java:340)
	at org.testng.SuiteRunner.run(SuiteRunner.java:289)
	at org.testng.SuiteRunnerWorker.runSuite(SuiteRunnerWorker.java:52)
	at org.testng.SuiteRunnerWorker.run(SuiteRunnerWorker.java:86)
	at org.testng.TestNG.runSuitesSequentially(TestNG.java:1301)
	at org.testng.TestNG.runSuitesLocally(TestNG.java:1226)
	at org.testng.TestNG.runSuites(TestNG.java:1144)
	at org.testng.TestNG.run(TestNG.java:1115)
	at org.testng.remote.AbstractRemoteTestNG.run(AbstractRemoteTestNG.java:132)
	at org.testng.remote.RemoteTestNG.initAndRun(RemoteTestNG.java:230)
	at org.testng.remote.RemoteTestNG.main(RemoteTestNG.java:76)
]]>
            </full-stacktrace>
          </exception> <!-- java.lang.AssertionError -->
          <reporter-output>
          </reporter-output>
        </test-method> <!-- Order_Certificates -->
        <test-method status="SKIP" signature="User_Login()[pri:0, instance:Sanity_Test.Test_ErrorFix@63753b6d]" name="User_Login" is-config="true" duration-ms="0" started-at="2017-08-03T17:07:20Z" finished-at="2017-08-03T17:07:20Z">
          <reporter-output>
          </reporter-output>
        </test-method> <!-- User_Login -->
        <test-method status="SKIP" signature="Order_Certificates(java.lang.String, java.lang.String)[pri:1, instance:Sanity_Test.Test_ErrorFix@63753b6d]" name="Order_Certificates" duration-ms="0" started-at="2017-08-03T17:07:20Z" data-provider="OrderProduct_Data" finished-at="2017-08-03T17:07:20Z">
          <exception class="java.lang.AssertionError">
            <message>
              <![CDATA[Log Out not visible]]>
            </message>
            <full-stacktrace>
              <![CDATA[java.lang.AssertionError: Log Out not visible
	at org.testng.Assert.fail(Assert.java:93)
	at Sanity_Test.Test_ErrorFix.User_Logout(Test_ErrorFix.java:119)
	at sun.reflect.NativeMethodAccessorImpl.invoke0(Native Method)
	at sun.reflect.NativeMethodAccessorImpl.invoke(NativeMethodAccessorImpl.java:62)
	at sun.reflect.DelegatingMethodAccessorImpl.invoke(DelegatingMethodAccessorImpl.java:43)
	at java.lang.reflect.Method.invoke(Method.java:498)
	at org.testng.internal.MethodInvocationHelper.invokeMethod(MethodInvocationHelper.java:108)
	at org.testng.internal.Invoker.invokeConfigurationMethod(Invoker.java:523)
	at org.testng.internal.Invoker.invokeConfigurations(Invoker.java:224)
	at org.testng.internal.Invoker.invokeMethod(Invoker.java:723)
	at org.testng.internal.Invoker.invokeTestMethod(Invoker.java:869)
	at org.testng.internal.Invoker.invokeTestMethods(Invoker.java:1193)
	at org.testng.internal.TestMethodWorker.invokeTestMethods(TestMethodWorker.java:126)
	at org.testng.internal.TestMethodWorker.run(TestMethodWorker.java:109)
	at org.testng.TestRunner.privateRun(TestRunner.java:744)
	at org.testng.TestRunner.run(TestRunner.java:602)
	at org.testng.SuiteRunner.runTest(SuiteRunner.java:380)
	at org.testng.SuiteRunner.runSequentially(SuiteRunner.java:375)
	at org.testng.SuiteRunner.privateRun(SuiteRunner.java:340)
	at org.testng.SuiteRunner.run(SuiteRunner.java:289)
	at org.testng.SuiteRunnerWorker.runSuite(SuiteRunnerWorker.java:52)
	at org.testng.SuiteRunnerWorker.run(SuiteRunnerWorker.java:86)
	at org.testng.TestNG.runSuitesSequentially(TestNG.java:1301)
	at org.testng.TestNG.runSuitesLocally(TestNG.java:1226)
	at org.testng.TestNG.runSuites(TestNG.java:1144)
	at org.testng.TestNG.run(TestNG.java:1115)
	at org.testng.remote.AbstractRemoteTestNG.run(AbstractRemoteTestNG.java:132)
	at org.testng.remote.RemoteTestNG.initAndRun(RemoteTestNG.java:230)
	at org.testng.remote.RemoteTestNG.main(RemoteTestNG.java:76)
]]>
            </full-stacktrace>
          </exception> <!-- java.lang.AssertionError -->
          <reporter-output>
          </reporter-output>
        </test-method> <!-- Order_Certificates -->
        <test-method status="SKIP" signature="User_Login()[pri:0, instance:Sanity_Test.Test_ErrorFix@63753b6d]" name="User_Login" is-config="true" duration-ms="0" started-at="2017-08-03T17:07:20Z" finished-at="2017-08-03T17:07:20Z">
          <reporter-output>
          </reporter-output>
        </test-method> <!-- User_Login -->
        <test-method status="SKIP" signature="Order_Certificates(java.lang.String, java.lang.String)[pri:1, instance:Sanity_Test.Test_ErrorFix@63753b6d]" name="Order_Certificates" duration-ms="0" started-at="2017-08-03T17:07:20Z" data-provider="OrderProduct_Data" finished-at="2017-08-03T17:07:20Z">
          <exception class="java.lang.AssertionError">
            <message>
              <![CDATA[Log Out not visible]]>
            </message>
            <full-stacktrace>
              <![CDATA[java.lang.AssertionError: Log Out not visible
	at org.testng.Assert.fail(Assert.java:93)
	at Sanity_Test.Test_ErrorFix.User_Logout(Test_ErrorFix.java:119)
	at sun.reflect.NativeMethodAccessorImpl.invoke0(Native Method)
	at sun.reflect.NativeMethodAccessorImpl.invoke(NativeMethodAccessorImpl.java:62)
	at sun.reflect.DelegatingMethodAccessorImpl.invoke(DelegatingMethodAccessorImpl.java:43)
	at java.lang.reflect.Method.invoke(Method.java:498)
	at org.testng.internal.MethodInvocationHelper.invokeMethod(MethodInvocationHelper.java:108)
	at org.testng.internal.Invoker.invokeConfigurationMethod(Invoker.java:523)
	at org.testng.internal.Invoker.invokeConfigurations(Invoker.java:224)
	at org.testng.internal.Invoker.invokeMethod(Invoker.java:723)
	at org.testng.internal.Invoker.invokeTestMethod(Invoker.java:869)
	at org.testng.internal.Invoker.invokeTestMethods(Invoker.java:1193)
	at org.testng.internal.TestMethodWorker.invokeTestMethods(TestMethodWorker.java:126)
	at org.testng.internal.TestMethodWorker.run(TestMethodWorker.java:109)
	at org.testng.TestRunner.privateRun(TestRunner.java:744)
	at org.testng.TestRunner.run(TestRunner.java:602)
	at org.testng.SuiteRunner.runTest(SuiteRunner.java:380)
	at org.testng.SuiteRunner.runSequentially(SuiteRunner.java:375)
	at org.testng.SuiteRunner.privateRun(SuiteRunner.java:340)
	at org.testng.SuiteRunner.run(SuiteRunner.java:289)
	at org.testng.SuiteRunnerWorker.runSuite(SuiteRunnerWorker.java:52)
	at org.testng.SuiteRunnerWorker.run(SuiteRunnerWorker.java:86)
	at org.testng.TestNG.runSuitesSequentially(TestNG.java:1301)
	at org.testng.TestNG.runSuitesLocally(TestNG.java:1226)
	at org.testng.TestNG.runSuites(TestNG.java:1144)
	at org.testng.TestNG.run(TestNG.java:1115)
	at org.testng.remote.AbstractRemoteTestNG.run(AbstractRemoteTestNG.java:132)
	at org.testng.remote.RemoteTestNG.initAndRun(RemoteTestNG.java:230)
	at org.testng.remote.RemoteTestNG.main(RemoteTestNG.java:76)
]]>
            </full-stacktrace>
          </exception> <!-- java.lang.AssertionError -->
          <reporter-output>
          </reporter-output>
        </test-method> <!-- Order_Certificates -->
        <test-method status="SKIP" signature="User_Login()[pri:0, instance:Sanity_Test.Test_ErrorFix@63753b6d]" name="User_Login" is-config="true" duration-ms="0" started-at="2017-08-03T17:07:20Z" finished-at="2017-08-03T17:07:20Z">
          <reporter-output>
          </reporter-output>
        </test-method> <!-- User_Login -->
        <test-method status="SKIP" signature="Order_Certificates(java.lang.String, java.lang.String)[pri:1, instance:Sanity_Test.Test_ErrorFix@63753b6d]" name="Order_Certificates" duration-ms="0" started-at="2017-08-03T17:07:20Z" data-provider="OrderProduct_Data" finished-at="2017-08-03T17:07:20Z">
          <exception class="java.lang.AssertionError">
            <message>
              <![CDATA[Log Out not visible]]>
            </message>
            <full-stacktrace>
              <![CDATA[java.lang.AssertionError: Log Out not visible
	at org.testng.Assert.fail(Assert.java:93)
	at Sanity_Test.Test_ErrorFix.User_Logout(Test_ErrorFix.java:119)
	at sun.reflect.NativeMethodAccessorImpl.invoke0(Native Method)
	at sun.reflect.NativeMethodAccessorImpl.invoke(NativeMethodAccessorImpl.java:62)
	at sun.reflect.DelegatingMethodAccessorImpl.invoke(DelegatingMethodAccessorImpl.java:43)
	at java.lang.reflect.Method.invoke(Method.java:498)
	at org.testng.internal.MethodInvocationHelper.invokeMethod(MethodInvocationHelper.java:108)
	at org.testng.internal.Invoker.invokeConfigurationMethod(Invoker.java:523)
	at org.testng.internal.Invoker.invokeConfigurations(Invoker.java:224)
	at org.testng.internal.Invoker.invokeMethod(Invoker.java:723)
	at org.testng.internal.Invoker.invokeTestMethod(Invoker.java:869)
	at org.testng.internal.Invoker.invokeTestMethods(Invoker.java:1193)
	at org.testng.internal.TestMethodWorker.invokeTestMethods(TestMethodWorker.java:126)
	at org.testng.internal.TestMethodWorker.run(TestMethodWorker.java:109)
	at org.testng.TestRunner.privateRun(TestRunner.java:744)
	at org.testng.TestRunner.run(TestRunner.java:602)
	at org.testng.SuiteRunner.runTest(SuiteRunner.java:380)
	at org.testng.SuiteRunner.runSequentially(SuiteRunner.java:375)
	at org.testng.SuiteRunner.privateRun(SuiteRunner.java:340)
	at org.testng.SuiteRunner.run(SuiteRunner.java:289)
	at org.testng.SuiteRunnerWorker.runSuite(SuiteRunnerWorker.java:52)
	at org.testng.SuiteRunnerWorker.run(SuiteRunnerWorker.java:86)
	at org.testng.TestNG.runSuitesSequentially(TestNG.java:1301)
	at org.testng.TestNG.runSuitesLocally(TestNG.java:1226)
	at org.testng.TestNG.runSuites(TestNG.java:1144)
	at org.testng.TestNG.run(TestNG.java:1115)
	at org.testng.remote.AbstractRemoteTestNG.run(AbstractRemoteTestNG.java:132)
	at org.testng.remote.RemoteTestNG.initAndRun(RemoteTestNG.java:230)
	at org.testng.remote.RemoteTestNG.main(RemoteTestNG.java:76)
]]>
            </full-stacktrace>
          </exception> <!-- java.lang.AssertionError -->
          <reporter-output>
          </reporter-output>
        </test-method> <!-- Order_Certificates -->
        <test-method status="SKIP" signature="afterTest()[pri:0, instance:Sanity_Test.Test_ErrorFix@63753b6d]" name="afterTest" is-config="true" duration-ms="0" started-at="2017-08-03T17:07:20Z" finished-at="2017-08-03T17:07:20Z">
          <reporter-output>
          </reporter-output>
        </test-method> <!-- afterTest -->
      </class> <!-- Sanity_Test.Test_ErrorFix -->
    </test> <!-- Default test -->
  </suite> <!-- Default suite -->
</testng-results>
